Workbook

Sheet Theme Summary
A1: Conversation View feedback - theme summary
A2: Counts are unique feedback records confidently classified into each sub-theme. 'Number of Comments' is a live COUNT over the matching sub-theme sheet, so the summary always reconciles with the detail.
A4: Scope of analysis
A5: Total feedback records reviewed | B5: 757
A6: Feedback date range | B6: 14 Oct 2020 to 18 Aug 2026
A7: Quarters covered | B7: 24 (Q4 2020 to Q3 2026)
A8: Unique accounts | B8: 654
A9: Records classified into at least one sub-theme | B9: 460 | C9: =B9/B5 -> 0.60766182 | D9: of all records reviewed
A10: Records not classified | B10: =COUNT('Unclassified Feedback'!$A$2:$A$2000) -> 297 | C10: =B10/B5 -> 0.39233818 | D10: specific problem not identifiable from the text - see Unclassified Feedback sheet
A11: Total sub-theme assignments (a record may span several) | B11: =F29 -> 545
A12: Records mapped to more than one sub-theme | B12: 80 | C12: =B12/B9 -> 0.17391304 | D12: drives the gap between records classified and total assignments
A13: Sub-themes with at least one classified comment | B13: =COUNTIF($F$16:$F$28,">0")&" of "&COUNTA($B$16:$B$28) -> 12 of 13
A15: Theme | B15: Sub-theme | C15: Problem / Story | D15: Top comment highlights and account | E15: Comment | F15: Number of Comments
A16: Thread navigation & message discovery | B16: Message ordering | C16: I can't view the conversation in the chronological order that feels natural to me. | D16: "there is no flow in the message. top to bottom. new message comes in the middle instead" - Account 5197887, 2026-08-11 "the latest response pops up in the middle" - Account 9166325, 2026-05-04 "The email threads arent in chronological order" - Account 162102, 2025-08-03 | F16: =COUNT('Message Ordering'!$B$2:$B$2000) -> 94
A17: Thread navigation & message discovery | B17: Jump to latest message | C17: I have to manually scroll through long threads to find the newest message, and currently I am landed on the last unread message. | D17: "I have to scroll through all the past emails to find the latest one" - Account 7980726, 2026-03-19 "in a trailed email, it is very hard to find the last one that came in" - Account 4866745, 2026-05-08 "very hard to se the most recent message" - Account 10662219, 2026-06-30 | F17: =COUNT('Jump to Latest'!$B$2:$B$2000) -> 69
A18: Thread navigation & message discovery | B18: Finding a specific message | C18: I have to search through or expand a long thread to find a specific earlier message or piece of information. | D18: "it is more of a struggle to find a specific one by the date it was sent" - Account 10767743, 2026-07-20 "It takes an age to find a particular email" - Account 3836964, 2025-08-15 "they pile up and it is hard to find an email within the thread" - Account 3374249, 2026-02-19 | F18: =COUNT('Find Specific Message'!$B$2:$B$2000) -> 80
A19: Thread navigation & message discovery | B19: Read/unread visibility | C19: I can't easily tell which messages inside a thread I have already read. | D19: No comments confidently classified into this sub-theme. | F19: =COUNT('Read-Unread Visibility'!$B$2:$B$2000) -> 0
A20: Message actions | B20: Mark individual message unread | C20: I can't manage the read state of a specific email independently from the rest of the thread. | D20: "Mark individual emails unread rather than full threads" - Account 1348064, 2022-07-21 "you can mark just one email as unread from a thread" - Account 6764889, 2026-02-09 "I would like to be able to mark a read email as new" - Account 6712333, 2025-11-25 | F20: =COUNT('Mark Message Unread'!$B$2:$B$2000) -> 3
A21: Conversation grouping & boundaries | B21: Disable Conversation View | C21: I'm forced to consume emails as grouped conversations even when I prefer individual messages. | D21: "You cannot change email from conversation view to single email view" - Account 9235848, 2026-05-06 "Provide an options where emails do not need to be grouped by thread, but can be separated into their own email" - Account 216696, 2026-04-20 "I cant change from conversation mode to single email" - Account 7956637, 2026-03-23 | E21: Fixed | F21: =COUNT('Disable Conversation'!$B$2:$B$2000) -> 197
A22: Conversation grouping & boundaries | B22: Separate conversation branches | C22: Replies and forwards meant for different audiences or contexts get appended to the same conversation, making it difficult to distinguish separate discussion branches and understand who saw what. | D22: "If one forwards an email to someone else, it should not then be part of the old email chain" - Account 6712333, 2025-11-25 "It groups emails and histories under the same subject; the recipients are sometimes different" - Account 6755629, 2026-02-07 "they are grouped under one even I change recipients in responding emails" - Account 3726421, 2025-03-08 | F22: =COUNT('Separate Branches'!$B$2:$B$2000) -> 23
A23: Thread readability & structure | B23: Nested / quoted content readability | C23: When an email has been replied to or forwarded repeatedly, the quoted history keeps getting narrower or hidden until older content becomes extremely difficult or impossible to read. | D23: "the email history makes it harder to check the messages because they keep "shrinking" towards the right-hand side" - Account 7914516, 2026-05-11 "Reading through a quoted email thread that you weren't part of is practically impossible" - Account 648473, 2026-06-16 "The message block becomes thinner and thinner, until each word in the email becomes a new line" - Account 1193270, 2022-06-21 | F23: =COUNT('Quoted Readability'!$B$2:$B$2000) -> 9
A24: Attachments in threads | B24: Attachment discovery & access | C24: I have to search through individual messages to find attachments in a long conversation. | D24: "THE ATTACHMENTS FROM OTJHER EMAILS ARE IMPOSSIBLE TO FIND" - Account 7436174, 2025-10-24 "you have to scroll to the bottom of the entire thread in order to see the attachments for a recent response" - Account 8023722, 2026-04-03 "struggling to find a file attached to an email in the thread" - Account 7245148, 2026-05-06 | F24: =COUNT('Attachment Discovery'!$B$2:$B$2000) -> 29
A25: Attachments in threads | B25: Attachment carry-over | C25: When I reply or forward within a thread, I can't easily control whether attachments from earlier messages should be included or excluded. | D25: "attached files do not come through in the email when they are replied to" - Account 6276279, 2025-01-06 | F25: =COUNT('Attachment Carry-over'!$B$2:$B$2000) -> 1
A26: Thread reliability | B26: Message rendering | C26: When I open older messages in a thread, content can appear duplicated, hidden behind ellipses, badly formatted, or with images missing, so I can't trust that I'm seeing the complete original email. | D26: "the newest email in a thread does not load and i cant see it until i press the reply button" - Account 3305982, 2026-05-04 "The root email is repeated in the chain over and over again" - Account 7578799, 2026-04-16 "Sometimes the text of email threads vanish under ... ellipses" - Account 3104383, 2026-05-16 | F26: =COUNT('Message Rendering'!$B$2:$B$2000) -> 29
A27: Thread sharing | B27: Attach conversation to a new email | C27: When I want to share an existing email conversation with someone new, I can't attach the full thread to a new email as one object. | D27: "It is not possible to attach email threads to new emails" - Account 8525088, 2026-06-12 "Give an option to forward email threads as an attachment" - Account 9494030, 2026-08-18 | F27: =COUNT('Attach Conversation'!$B$2:$B$2000) -> 2
A28: Thread sharing | B28: Print full conversation | C28: When I print an email conversation, I can't reliably get one clean copy of the complete thread without messages being missed or duplicated. | D28: "In single message print .... it should print whole thread. In general print email ... it should avoid duplication print of same message" - Account 6178215, 2025-11-24 "it prints the whole string, repeating some messages multiple times" - Account 167088, 2021-04-04 "Most email threads can't be printed--it's a blank screen when I choose "print conversation."" - Account 917360, 2022-05-11 | F28: =COUNT('Print Conversation'!$B$2:$B$2000) -> 9
D29: Total classified records (a record may appear under more than one sub-theme) | F29: =SUM(F16:F28) -> 545

Sheet Quarterly Trend
A1: Classified comments per sub-theme, by quarter (newest to oldest)
A2: Quarter derived from Feedback Date. Cells are COUNTIFS over the sub-theme sheets, so they reconcile with the detail sheets.
A4: Theme | B4: Sub-theme | C4: Q3 2026 | D4: Q2 2026 | E4: Q1 2026 | F4: Q4 2025 | G4: Q3 2025 | H4: Q2 2025 | I4: Q1 2025 | J4: Q4 2024 | K4: Q3 2024 | L4: Q2 2024 | M4: Q1 2024 | N4: Q4 2023 | O4: Q3 2023 | P4: Q2 2023 | Q4: Q1 2023 | R4: Q4 2022 | S4: Q3 2022 | T4: Q2 2022 | U4: Q1 2022 | V4: Q4 2021 | W4: Q3 2021 | X4: Q2 2021 | Y4: Q1 2021 | Z4: Q4 2020
A5: Thread navigation & message discovery | B5: Message ordering | C5: =COUNTIFS('Message Ordering'!$C$2:$C$2000,">="&DATE(2026,7,1),'Message Ordering'!$C$2:$C$2000,"<="&DATE(2026,9,30)) -> 4 | D5: =COUNTIFS('Message Ordering'!$C$2:$C$2000,">="&DATE(2026,4,1),'Message Ordering'!$C$2:$C$2000,"<="&DATE(2026,6,30)) -> 6 | E5: =COUNTIFS('Message Ordering'!$C$2:$C$2000,">="&DATE(2026,1,1),'Message Ordering'!$C$2:$C$2000,"<="&DATE(2026,3,31)) -> 3 | F5: =COUNTIFS('Message Ordering'!$C$2:$C$2000,">="&DATE(2025,10,1),'Message Ordering'!$C$2:$C$2000,"<="&DATE(2025,12,31)) -> 7 | G5: =COUNTIFS('Message Ordering'!$C$2:$C$2000,">="&DATE(2025,7,1),'Message Ordering'!$C$2:$C$2000,"<="&DATE(2025,9,30)) -> 5 | H5: =COUNTIFS('Message Ordering'!$C$2:$C$2000,">="&DATE(2025,4,1),'Message Ordering'!$C$2:$C$2000,"<="&DATE(2025,6,30)) -> 5 | I5: =COUNTIFS('Message Ordering'!$C$2:$C$2000,">="&DATE(2025,1,1),'Message Ordering'!$C$2:$C$2000,"<="&DATE(2025,3,31)) -> 5 | J5: =COUNTIFS('Message Ordering'!$C$2:$C$2000,">="&DATE(2024,10,1),'Message Ordering'!$C$2:$C$2000,"<="&DATE(2024,12,31)) -> 3 | K5: =COUNTIFS('Message Ordering'!$C$2:$C$2000,">="&DATE(2024,7,1),'Message Ordering'!$C$2:$C$2000,"<="&DATE(2024,9,30)) -> 6 | L5: =COUNTIFS('Message Ordering'!$C$2:$C$2000,">="&DATE(2024,4,1),'Message Ordering'!$C$2:$C$2000,"<="&DATE(2024,6,30)) -> 5 | M5: =COUNTIFS('Message Ordering'!$C$2:$C$2000,">="&DATE(2024,1,1),'Message Ordering'!$C$2:$C$2000,"<="&DATE(2024,3,31)) -> 5 | N5: =COUNTIFS('Message Ordering'!$C$2:$C$2000,">="&DATE(2023,10,1),'Message Ordering'!$C$2:$C$2000,"<="&DATE(2023,12,31)) -> 3 | O5: =COUNTIFS('Message Ordering'!$C$2:$C$2000,">="&DATE(2023,7,1),'Message Ordering'!$C$2:$C$2000,"<="&DATE(2023,9,30)) -> 7 | P5: =COUNTIFS('Message Ordering'!$C$2:$C$2000,">="&DATE(2023,4,1),'Message Ordering'!$C$2:$C$2000,"<="&DATE(2023,6,30)) -> 5 | Q5: =COUNTIFS('Message Ordering'!$C$2:$C$2000,">="&DATE(2023,1,1),'Message Ordering'!$C$2:$C$2000,"<="&DATE(2023,3,31)) -> 1 | R5: =COUNTIFS('Message Ordering'!$C$2:$C$2000,">="&DATE(2022,10,1),'Message Ordering'!$C$2:$C$2000,"<="&DATE(2022,12,31)) -> 3 | S5: =COUNTIFS('Message Ordering'!$C$2:$C$2000,">="&DATE(2022,7,1),'Message Ordering'!$C$2:$C$2000,"<="&DATE(2022,9,30)) -> 1 | T5: =COUNTIFS('Message Ordering'!$C$2:$C$2000,">="&DATE(2022,4,1),'Message Ordering'!$C$2:$C$2000,"<="&DATE(2022,6,30)) -> 3 | U5: =COUNTIFS('Message Ordering'!$C$2:$C$2000,">="&DATE(2022,1,1),'Message Ordering'!$C$2:$C$2000,"<="&DATE(2022,3,31)) -> 8 | V5: =COUNTIFS('Message Ordering'!$C$2:$C$2000,">="&DATE(2021,10,1),'Message Ordering'!$C$2:$C$2000,"<="&DATE(2021,12,31)) -> 3 | W5: =COUNTIFS('Message Ordering'!$C$2:$C$2000,">="&DATE(2021,7,1),'Message Ordering'!$C$2:$C$2000,"<="&DATE(2021,9,30)) -> 0 | X5: =COUNTIFS('Message Ordering'!$C$2:$C$2000,">="&DATE(2021,4,1),'Message Ordering'!$C$2:$C$2000,"<="&DATE(2021,6,30)) -> 5 | Y5: =COUNTIFS('Message Ordering'!$C$2:$C$2000,">="&DATE(2021,1,1),'Message Ordering'!$C$2:$C$2000,"<="&DATE(2021,3,31)) -> 1 | Z5: =COUNTIFS('Message Ordering'!$C$2:$C$2000,">="&DATE(2020,10,1),'Message Ordering'!$C$2:$C$2000,"<="&DATE(2020,12,31)) -> 0
A6: Thread navigation & message discovery | B6: Jump to latest message | C6: =COUNTIFS('Jump to Latest'!$C$2:$C$2000,">="&DATE(2026,7,1),'Jump to Latest'!$C$2:$C$2000,"<="&DATE(2026,9,30)) -> 2 | D6: =COUNTIFS('Jump to Latest'!$C$2:$C$2000,">="&DATE(2026,4,1),'Jump to Latest'!$C$2:$C$2000,"<="&DATE(2026,6,30)) -> 6 | E6: =COUNTIFS('Jump to Latest'!$C$2:$C$2000,">="&DATE(2026,1,1),'Jump to Latest'!$C$2:$C$2000,"<="&DATE(2026,3,31)) -> 4 | F6: =COUNTIFS('Jump to Latest'!$C$2:$C$2000,">="&DATE(2025,10,1),'Jump to Latest'!$C$2:$C$2000,"<="&DATE(2025,12,31)) -> 1 | G6: =COUNTIFS('Jump to Latest'!$C$2:$C$2000,">="&DATE(2025,7,1),'Jump to Latest'!$C$2:$C$2000,"<="&DATE(2025,9,30)) -> 2 | H6: =COUNTIFS('Jump to Latest'!$C$2:$C$2000,">="&DATE(2025,4,1),'Jump to Latest'!$C$2:$C$2000,"<="&DATE(2025,6,30)) -> 2 | I6: =COUNTIFS('Jump to Latest'!$C$2:$C$2000,">="&DATE(2025,1,1),'Jump to Latest'!$C$2:$C$2000,"<="&DATE(2025,3,31)) -> 1 | J6: =COUNTIFS('Jump to Latest'!$C$2:$C$2000,">="&DATE(2024,10,1),'Jump to Latest'!$C$2:$C$2000,"<="&DATE(2024,12,31)) -> 2 | K6: =COUNTIFS('Jump to Latest'!$C$2:$C$2000,">="&DATE(2024,7,1),'Jump to Latest'!$C$2:$C$2000,"<="&DATE(2024,9,30)) -> 2 | L6: =COUNTIFS('Jump to Latest'!$C$2:$C$2000,">="&DATE(2024,4,1),'Jump to Latest'!$C$2:$C$2000,"<="&DATE(2024,6,30)) -> 0 | M6: =COUNTIFS('Jump to Latest'!$C$2:$C$2000,">="&DATE(2024,1,1),'Jump to Latest'!$C$2:$C$2000,"<="&DATE(2024,3,31)) -> 1 | N6: =COUNTIFS('Jump to Latest'!$C$2:$C$2000,">="&DATE(2023,10,1),'Jump to Latest'!$C$2:$C$2000,"<="&DATE(2023,12,31)) -> 1 | O6: =COUNTIFS('Jump to Latest'!$C$2:$C$2000,">="&DATE(2023,7,1),'Jump to Latest'!$C$2:$C$2000,"<="&DATE(2023,9,30)) -> 3 | P6: =COUNTIFS('Jump to Latest'!$C$2:$C$2000,">="&DATE(2023,4,1),'Jump to Latest'!$C$2:$C$2000,"<="&DATE(2023,6,30)) -> 9 | Q6: =COUNTIFS('Jump to Latest'!$C$2:$C$2000,">="&DATE(2023,1,1),'Jump to Latest'!$C$2:$C$2000,"<="&DATE(2023,3,31)) -> 6 | R6: =COUNTIFS('Jump to Latest'!$C$2:$C$2000,">="&DATE(2022,10,1),'Jump to Latest'!$C$2:$C$2000,"<="&DATE(2022,12,31)) -> 3 | S6: =COUNTIFS('Jump to Latest'!$C$2:$C$2000,">="&DATE(2022,7,1),'Jump to Latest'!$C$2:$C$2000,"<="&DATE(2022,9,30)) -> 2 | T6: =COUNTIFS('Jump to Latest'!$C$2:$C$2000,">="&DATE(2022,4,1),'Jump to Latest'!$C$2:$C$2000,"<="&DATE(2022,6,30)) -> 8 | U6: =COUNTIFS('Jump to Latest'!$C$2:$C$2000,">="&DATE(2022,1,1),'Jump to Latest'!$C$2:$C$2000,"<="&DATE(2022,3,31)) -> 9 | V6: =COUNTIFS('Jump to Latest'!$C$2:$C$2000,">="&DATE(2021,10,1),'Jump to Latest'!$C$2:$C$2000,"<="&DATE(2021,12,31)) -> 1 | W6: =COUNTIFS('Jump to Latest'!$C$2:$C$2000,">="&DATE(2021,7,1),'Jump to Latest'!$C$2:$C$2000,"<="&DATE(2021,9,30)) -> 1 | X6: =COUNTIFS('Jump to Latest'!$C$2:$C$2000,">="&DATE(2021,4,1),'Jump to Latest'!$C$2:$C$2000,"<="&DATE(2021,6,30)) -> 2 | Y6: =COUNTIFS('Jump to Latest'!$C$2:$C$2000,">="&DATE(2021,1,1),'Jump to Latest'!$C$2:$C$2000,"<="&DATE(2021,3,31)) -> 1 | Z6: =COUNTIFS('Jump to Latest'!$C$2:$C$2000,">="&DATE(2020,10,1),'Jump to Latest'!$C$2:$C$2000,"<="&DATE(2020,12,31)) -> 0
A7: Thread navigation & message discovery | B7: Finding a specific message | C7: =COUNTIFS('Find Specific Message'!$C$2:$C$2000,">="&DATE(2026,7,1),'Find Specific Message'!$C$2:$C$2000,"<="&DATE(2026,9,30)) -> 1 | D7: =COUNTIFS('Find Specific Message'!$C$2:$C$2000,">="&DATE(2026,4,1),'Find Specific Message'!$C$2:$C$2000,"<="&DATE(2026,6,30)) -> 8 | E7: =COUNTIFS('Find Specific Message'!$C$2:$C$2000,">="&DATE(2026,1,1),'Find Specific Message'!$C$2:$C$2000,"<="&DATE(2026,3,31)) -> 2 | F7: =COUNTIFS('Find Specific Message'!$C$2:$C$2000,">="&DATE(2025,10,1),'Find Specific Message'!$C$2:$C$2000,"<="&DATE(2025,12,31)) -> 3 | G7: =COUNTIFS('Find Specific Message'!$C$2:$C$2000,">="&DATE(2025,7,1),'Find Specific Message'!$C$2:$C$2000,"<="&DATE(2025,9,30)) -> 3 | H7: =COUNTIFS('Find Specific Message'!$C$2:$C$2000,">="&DATE(2025,4,1),'Find Specific Message'!$C$2:$C$2000,"<="&DATE(2025,6,30)) -> 3 | I7: =COUNTIFS('Find Specific Message'!$C$2:$C$2000,">="&DATE(2025,1,1),'Find Specific Message'!$C$2:$C$2000,"<="&DATE(2025,3,31)) -> 5 | J7: =COUNTIFS('Find Specific Message'!$C$2:$C$2000,">="&DATE(2024,10,1),'Find Specific Message'!$C$2:$C$2000,"<="&DATE(2024,12,31)) -> 1 | K7: =COUNTIFS('Find Specific Message'!$C$2:$C$2000,">="&DATE(2024,7,1),'Find Specific Message'!$C$2:$C$2000,"<="&DATE(2024,9,30)) -> 3 | L7: =COUNTIFS('Find Specific Message'!$C$2:$C$2000,">="&DATE(2024,4,1),'Find Specific Message'!$C$2:$C$2000,"<="&DATE(2024,6,30)) -> 3 | M7: =COUNTIFS('Find Specific Message'!$C$2:$C$2000,">="&DATE(2024,1,1),'Find Specific Message'!$C$2:$C$2000,"<="&DATE(2024,3,31)) -> 3 | N7: =COUNTIFS('Find Specific Message'!$C$2:$C$2000,">="&DATE(2023,10,1),'Find Specific Message'!$C$2:$C$2000,"<="&DATE(2023,12,31)) -> 2 | O7: =COUNTIFS('Find Specific Message'!$C$2:$C$2000,">="&DATE(2023,7,1),'Find Specific Message'!$C$2:$C$2000,"<="&DATE(2023,9,30)) -> 2 | P7: =COUNTIFS('Find Specific Message'!$C$2:$C$2000,">="&DATE(2023,4,1),'Find Specific Message'!$C$2:$C$2000,"<="&DATE(2023,6,30)) -> 2 | Q7: =COUNTIFS('Find Specific Message'!$C$2:$C$2000,">="&DATE(2023,1,1),'Find Specific Message'!$C$2:$C$2000,"<="&DATE(2023,3,31)) -> 4 | R7: =COUNTIFS('Find Specific Message'!$C$2:$C$2000,">="&DATE(2022,10,1),'Find Specific Message'!$C$2:$C$2000,"<="&DATE(2022,12,31)) -> 1 | S7: =COUNTIFS('Find Specific Message'!$C$2:$C$2000,">="&DATE(2022,7,1),'Find Specific Message'!$C$2:$C$2000,"<="&DATE(2022,9,30)) -> 9 | T7: =COUNTIFS('Find Specific Message'!$C$2:$C$2000,">="&DATE(2022,4,1),'Find Specific Message'!$C$2:$C$2000,"<="&DATE(2022,6,30)) -> 9 | U7: =COUNTIFS('Find Specific Message'!$C$2:$C$2000,">="&DATE(2022,1,1),'Find Specific Message'!$C$2:$C$2000,"<="&DATE(2022,3,31)) -> 3 | V7: =COUNTIFS('Find Specific Message'!$C$2:$C$2000,">="&DATE(2021,10,1),'Find Specific Message'!$C$2:$C$2000,"<="&DATE(2021,12,31)) -> 5 | W7: =COUNTIFS('Find Specific Message'!$C$2:$C$2000,">="&DATE(2021,7,1),'Find Specific Message'!$C$2:$C$2000,"<="&DATE(2021,9,30)) -> 2 | X7: =COUNTIFS('Find Specific Message'!$C$2:$C$2000,">="&DATE(2021,4,1),'Find Specific Message'!$C$2:$C$2000,"<="&DATE(2021,6,30)) -> 4 | Y7: =COUNTIFS('Find Specific Message'!$C$2:$C$2000,">="&DATE(2021,1,1),'Find Specific Message'!$C$2:$C$2000,"<="&DATE(2021,3,31)) -> 1 | Z7: =COUNTIFS('Find Specific Message'!$C$2:$C$2000,">="&DATE(2020,10,1),'Find Specific Message'!$C$2:$C$2000,"<="&DATE(2020,12,31)) -> 1
A8: Thread navigation & message discovery | B8: Read/unread visibility | C8: =COUNTIFS('Read-Unread Visibility'!$C$2:$C$2000,">="&DATE(2026,7,1),'Read-Unread Visibility'!$C$2:$C$2000,"<="&DATE(2026,9,30)) -> 0 | D8: =COUNTIFS('Read-Unread Visibility'!$C$2:$C$2000,">="&DATE(2026,4,1),'Read-Unread Visibility'!$C$2:$C$2000,"<="&DATE(2026,6,30)) -> 0 | E8: =COUNTIFS('Read-Unread Visibility'!$C$2:$C$2000,">="&DATE(2026,1,1),'Read-Unread Visibility'!$C$2:$C$2000,"<="&DATE(2026,3,31)) -> 0 | F8: =COUNTIFS('Read-Unread Visibility'!$C$2:$C$2000,">="&DATE(2025,10,1),'Read-Unread Visibility'!$C$2:$C$2000,"<="&DATE(2025,12,31)) -> 0 | G8: =COUNTIFS('Read-Unread Visibility'!$C$2:$C$2000,">="&DATE(2025,7,1),'Read-Unread Visibility'!$C$2:$C$2000,"<="&DATE(2025,9,30)) -> 0 | H8: =COUNTIFS('Read-Unread Visibility'!$C$2:$C$2000,">="&DATE(2025,4,1),'Read-Unread Visibility'!$C$2:$C$2000,"<="&DATE(2025,6,30)) -> 0 | I8: =COUNTIFS('Read-Unread Visibility'!$C$2:$C$2000,">="&DATE(2025,1,1),'Read-Unread Visibility'!$C$2:$C$2000,"<="&DATE(2025,3,31)) -> 0 | J8: =COUNTIFS('Read-Unread Visibility'!$C$2:$C$2000,">="&DATE(2024,10,1),'Read-Unread Visibility'!$C$2:$C$2000,"<="&DATE(2024,12,31)) -> 0 | K8: =COUNTIFS('Read-Unread Visibility'!$C$2:$C$2000,">="&DATE(2024,7,1),'Read-Unread Visibility'!$C$2:$C$2000,"<="&DATE(2024,9,30)) -> 0 | L8: =COUNTIFS('Read-Unread Visibility'!$C$2:$C$2000,">="&DATE(2024,4,1),'Read-Unread Visibility'!$C$2:$C$2000,"<="&DATE(2024,6,30)) -> 0 | M8: =COUNTIFS('Read-Unread Visibility'!$C$2:$C$2000,">="&DATE(2024,1,1),'Read-Unread Visibility'!$C$2:$C$2000,"<="&DATE(2024,3,31)) -> 0 | N8: =COUNTIFS('Read-Unread Visibility'!$C$2:$C$2000,">="&DATE(2023,10,1),'Read-Unread Visibility'!$C$2:$C$2000,"<="&DATE(2023,12,31)) -> 0 | O8: =COUNTIFS('Read-Unread Visibility'!$C$2:$C$2000,">="&DATE(2023,7,1),'Read-Unread Visibility'!$C$2:$C$2000,"<="&DATE(2023,9,30)) -> 0 | P8: =COUNTIFS('Read-Unread Visibility'!$C$2:$C$2000,">="&DATE(2023,4,1),'Read-Unread Visibility'!$C$2:$C$2000,"<="&DATE(2023,6,30)) -> 0 | Q8: =COUNTIFS('Read-Unread Visibility'!$C$2:$C$2000,">="&DATE(2023,1,1),'Read-Unread Visibility'!$C$2:$C$2000,"<="&DATE(2023,3,31)) -> 0 | R8: =COUNTIFS('Read-Unread Visibility'!$C$2:$C$2000,">="&DATE(2022,10,1),'Read-Unread Visibility'!$C$2:$C$2000,"<="&DATE(2022,12,31)) -> 0 | S8: =COUNTIFS('Read-Unread Visibility'!$C$2:$C$2000,">="&DATE(2022,7,1),'Read-Unread Visibility'!$C$2:$C$2000,"<="&DATE(2022,9,30)) -> 0 | T8: =COUNTIFS('Read-Unread Visibility'!$C$2:$C$2000,">="&DATE(2022,4,1),'Read-Unread Visibility'!$C$2:$C$2000,"<="&DATE(2022,6,30)) -> 0 | U8: =COUNTIFS('Read-Unread Visibility'!$C$2:$C$2000,">="&DATE(2022,1,1),'Read-Unread Visibility'!$C$2:$C$2000,"<="&DATE(2022,3,31)) -> 0 | V8: =COUNTIFS('Read-Unread Visibility'!$C$2:$C$2000,">="&DATE(2021,10,1),'Read-Unread Visibility'!$C$2:$C$2000,"<="&DATE(2021,12,31)) -> 0 | W8: =COUNTIFS('Read-Unread Visibility'!$C$2:$C$2000,">="&DATE(2021,7,1),'Read-Unread Visibility'!$C$2:$C$2000,"<="&DATE(2021,9,30)) -> 0 | X8: =COUNTIFS('Read-Unread Visibility'!$C$2:$C$2000,">="&DATE(2021,4,1),'Read-Unread Visibility'!$C$2:$C$2000,"<="&DATE(2021,6,30)) -> 0 | Y8: =COUNTIFS('Read-Unread Visibility'!$C$2:$C$2000,">="&DATE(2021,1,1),'Read-Unread Visibility'!$C$2:$C$2000,"<="&DATE(2021,3,31)) -> 0 | Z8: =COUNTIFS('Read-Unread Visibility'!$C$2:$C$2000,">="&DATE(2020,10,1),'Read-Unread Visibility'!$C$2:$C$2000,"<="&DATE(2020,12,31)) -> 0
A9: Message actions | B9: Mark individual message unread | C9: =COUNTIFS('Mark Message Unread'!$C$2:$C$2000,">="&DATE(2026,7,1),'Mark Message Unread'!$C$2:$C$2000,"<="&DATE(2026,9,30)) -> 0 | D9: =COUNTIFS('Mark Message Unread'!$C$2:$C$2000,">="&DATE(2026,4,1),'Mark Message Unread'!$C$2:$C$2000,"<="&DATE(2026,6,30)) -> 0 | E9: =COUNTIFS('Mark Message Unread'!$C$2:$C$2000,">="&DATE(2026,1,1),'Mark Message Unread'!$C$2:$C$2000,"<="&DATE(2026,3,31)) -> 1 | F9: =COUNTIFS('Mark Message Unread'!$C$2:$C$2000,">="&DATE(2025,10,1),'Mark Message Unread'!$C$2:$C$2000,"<="&DATE(2025,12,31)) -> 1 | G9: =COUNTIFS('Mark Message Unread'!$C$2:$C$2000,">="&DATE(2025,7,1),'Mark Message Unread'!$C$2:$C$2000,"<="&DATE(2025,9,30)) -> 0 | H9: =COUNTIFS('Mark Message Unread'!$C$2:$C$2000,">="&DATE(2025,4,1),'Mark Message Unread'!$C$2:$C$2000,"<="&DATE(2025,6,30)) -> 0 | I9: =COUNTIFS('Mark Message Unread'!$C$2:$C$2000,">="&DATE(2025,1,1),'Mark Message Unread'!$C$2:$C$2000,"<="&DATE(2025,3,31)) -> 0 | J9: =COUNTIFS('Mark Message Unread'!$C$2:$C$2000,">="&DATE(2024,10,1),'Mark Message Unread'!$C$2:$C$2000,"<="&DATE(2024,12,31)) -> 0 | K9: =COUNTIFS('Mark Message Unread'!$C$2:$C$2000,">="&DATE(2024,7,1),'Mark Message Unread'!$C$2:$C$2000,"<="&DATE(2024,9,30)) -> 0 | L9: =COUNTIFS('Mark Message Unread'!$C$2:$C$2000,">="&DATE(2024,4,1),'Mark Message Unread'!$C$2:$C$2000,"<="&DATE(2024,6,30)) -> 0 | M9: =COUNTIFS('Mark Message Unread'!$C$2:$C$2000,">="&DATE(2024,1,1),'Mark Message Unread'!$C$2:$C$2000,"<="&DATE(2024,3,31)) -> 0 | N9: =COUNTIFS('Mark Message Unread'!$C$2:$C$2000,">="&DATE(2023,10,1),'Mark Message Unread'!$C$2:$C$2000,"<="&DATE(2023,12,31)) -> 0 | O9: =COUNTIFS('Mark Message Unread'!$C$2:$C$2000,">="&DATE(2023,7,1),'Mark Message Unread'!$C$2:$C$2000,"<="&DATE(2023,9,30)) -> 0 | P9: =COUNTIFS('Mark Message Unread'!$C$2:$C$2000,">="&DATE(2023,4,1),'Mark Message Unread'!$C$2:$C$2000,"<="&DATE(2023,6,30)) -> 0 | Q9: =COUNTIFS('Mark Message Unread'!$C$2:$C$2000,">="&DATE(2023,1,1),'Mark Message Unread'!$C$2:$C$2000,"<="&DATE(2023,3,31)) -> 0 | R9: =COUNTIFS('Mark Message Unread'!$C$2:$C$2000,">="&DATE(2022,10,1),'Mark Message Unread'!$C$2:$C$2000,"<="&DATE(2022,12,31)) -> 0 | S9: =COUNTIFS('Mark Message Unread'!$C$2:$C$2000,">="&DATE(2022,7,1),'Mark Message Unread'!$C$2:$C$2000,"<="&DATE(2022,9,30)) -> 1 | T9: =COUNTIFS('Mark Message Unread'!$C$2:$C$2000,">="&DATE(2022,4,1),'Mark Message Unread'!$C$2:$C$2000,"<="&DATE(2022,6,30)) -> 0 | U9: =COUNTIFS('Mark Message Unread'!$C$2:$C$2000,">="&DATE(2022,1,1),'Mark Message Unread'!$C$2:$C$2000,"<="&DATE(2022,3,31)) -> 0 | V9: =COUNTIFS('Mark Message Unread'!$C$2:$C$2000,">="&DATE(2021,10,1),'Mark Message Unread'!$C$2:$C$2000,"<="&DATE(2021,12,31)) -> 0 | W9: =COUNTIFS('Mark Message Unread'!$C$2:$C$2000,">="&DATE(2021,7,1),'Mark Message Unread'!$C$2:$C$2000,"<="&DATE(2021,9,30)) -> 0 | X9: =COUNTIFS('Mark Message Unread'!$C$2:$C$2000,">="&DATE(2021,4,1),'Mark Message Unread'!$C$2:$C$2000,"<="&DATE(2021,6,30)) -> 0 | Y9: =COUNTIFS('Mark Message Unread'!$C$2:$C$2000,">="&DATE(2021,1,1),'Mark Message Unread'!$C$2:$C$2000,"<="&DATE(2021,3,31)) -> 0 | Z9: =COUNTIFS('Mark Message Unread'!$C$2:$C$2000,">="&DATE(2020,10,1),'Mark Message Unread'!$C$2:$C$2000,"<="&DATE(2020,12,31)) -> 0
A10: Conversation grouping & boundaries | B10: Disable Conversation View | C10: =COUNTIFS('Disable Conversation'!$C$2:$C$2000,">="&DATE(2026,7,1),'Disable Conversation'!$C$2:$C$2000,"<="&DATE(2026,9,30)) -> 0 | D10: =COUNTIFS('Disable Conversation'!$C$2:$C$2000,">="&DATE(2026,4,1),'Disable Conversation'!$C$2:$C$2000,"<="&DATE(2026,6,30)) -> 4 | E10: =COUNTIFS('Disable Conversation'!$C$2:$C$2000,">="&DATE(2026,1,1),'Disable Conversation'!$C$2:$C$2000,"<="&DATE(2026,3,31)) -> 3 | F10: =COUNTIFS('Disable Conversation'!$C$2:$C$2000,">="&DATE(2025,10,1),'Disable Conversation'!$C$2:$C$2000,"<="&DATE(2025,12,31)) -> 1 | G10: =COUNTIFS('Disable Conversation'!$C$2:$C$2000,">="&DATE(2025,7,1),'Disable Conversation'!$C$2:$C$2000,"<="&DATE(2025,9,30)) -> 2 | H10: =COUNTIFS('Disable Conversation'!$C$2:$C$2000,">="&DATE(2025,4,1),'Disable Conversation'!$C$2:$C$2000,"<="&DATE(2025,6,30)) -> 5 | I10: =COUNTIFS('Disable Conversation'!$C$2:$C$2000,">="&DATE(2025,1,1),'Disable Conversation'!$C$2:$C$2000,"<="&DATE(2025,3,31)) -> 2 | J10: =COUNTIFS('Disable Conversation'!$C$2:$C$2000,">="&DATE(2024,10,1),'Disable Conversation'!$C$2:$C$2000,"<="&DATE(2024,12,31)) -> 4 | K10: =COUNTIFS('Disable Conversation'!$C$2:$C$2000,">="&DATE(2024,7,1),'Disable Conversation'!$C$2:$C$2000,"<="&DATE(2024,9,30)) -> 4 | L10: =COUNTIFS('Disable Conversation'!$C$2:$C$2000,">="&DATE(2024,4,1),'Disable Conversation'!$C$2:$C$2000,"<="&DATE(2024,6,30)) -> 4 | M10: =COUNTIFS('Disable Conversation'!$C$2:$C$2000,">="&DATE(2024,1,1),'Disable Conversation'!$C$2:$C$2000,"<="&DATE(2024,3,31)) -> 4 | N10: =COUNTIFS('Disable Conversation'!$C$2:$C$2000,">="&DATE(2023,10,1),'Disable Conversation'!$C$2:$C$2000,"<="&DATE(2023,12,31)) -> 6 | O10: =COUNTIFS('Disable Conversation'!$C$2:$C$2000,">="&DATE(2023,7,1),'Disable Conversation'!$C$2:$C$2000,"<="&DATE(2023,9,30)) -> 5 | P10: =COUNTIFS('Disable Conversation'!$C$2:$C$2000,">="&DATE(2023,4,1),'Disable Conversation'!$C$2:$C$2000,"<="&DATE(2023,6,30)) -> 8 | Q10: =COUNTIFS('Disable Conversation'!$C$2:$C$2000,">="&DATE(2023,1,1),'Disable Conversation'!$C$2:$C$2000,"<="&DATE(2023,3,31)) -> 12 | R10: =COUNTIFS('Disable Conversation'!$C$2:$C$2000,">="&DATE(2022,10,1),'Disable Conversation'!$C$2:$C$2000,"<="&DATE(2022,12,31)) -> 11 | S10: =COUNTIFS('Disable Conversation'!$C$2:$C$2000,">="&DATE(2022,7,1),'Disable Conversation'!$C$2:$C$2000,"<="&DATE(2022,9,30)) -> 29 | T10: =COUNTIFS('Disable Conversation'!$C$2:$C$2000,">="&DATE(2022,4,1),'Disable Conversation'!$C$2:$C$2000,"<="&DATE(2022,6,30)) -> 20 | U10: =COUNTIFS('Disable Conversation'!$C$2:$C$2000,">="&DATE(2022,1,1),'Disable Conversation'!$C$2:$C$2000,"<="&DATE(2022,3,31)) -> 18 | V10: =COUNTIFS('Disable Conversation'!$C$2:$C$2000,">="&DATE(2021,10,1),'Disable Conversation'!$C$2:$C$2000,"<="&DATE(2021,12,31)) -> 19 | W10: =COUNTIFS('Disable Conversation'!$C$2:$C$2000,">="&DATE(2021,7,1),'Disable Conversation'!$C$2:$C$2000,"<="&DATE(2021,9,30)) -> 15 | X10: =COUNTIFS('Disable Conversation'!$C$2:$C$2000,">="&DATE(2021,4,1),'Disable Conversation'!$C$2:$C$2000,"<="&DATE(2021,6,30)) -> 15 | Y10: =COUNTIFS('Disable Conversation'!$C$2:$C$2000,">="&DATE(2021,1,1),'Disable Conversation'!$C$2:$C$2000,"<="&DATE(2021,3,31)) -> 3 | Z10: =COUNTIFS('Disable Conversation'!$C$2:$C$2000,">="&DATE(2020,10,1),'Disable Conversation'!$C$2:$C$2000,"<="&DATE(2020,12,31)) -> 3
A11: Conversation grouping & boundaries | B11: Separate conversation branches | C11: =COUNTIFS('Separate Branches'!$C$2:$C$2000,">="&DATE(2026,7,1),'Separate Branches'!$C$2:$C$2000,"<="&DATE(2026,9,30)) -> 2 | D11: =COUNTIFS('Separate Branches'!$C$2:$C$2000,">="&DATE(2026,4,1),'Separate Branches'!$C$2:$C$2000,"<="&DATE(2026,6,30)) -> 2 | E11: =COUNTIFS('Separate Branches'!$C$2:$C$2000,">="&DATE(2026,1,1),'Separate Branches'!$C$2:$C$2000,"<="&DATE(2026,3,31)) -> 2 | F11: =COUNTIFS('Separate Branches'!$C$2:$C$2000,">="&DATE(2025,10,1),'Separate Branches'!$C$2:$C$2000,"<="&DATE(2025,12,31)) -> 1 | G11: =COUNTIFS('Separate Branches'!$C$2:$C$2000,">="&DATE(2025,7,1),'Separate Branches'!$C$2:$C$2000,"<="&DATE(2025,9,30)) -> 1 | H11: =COUNTIFS('Separate Branches'!$C$2:$C$2000,">="&DATE(2025,4,1),'Separate Branches'!$C$2:$C$2000,"<="&DATE(2025,6,30)) -> 1 | I11: =COUNTIFS('Separate Branches'!$C$2:$C$2000,">="&DATE(2025,1,1),'Separate Branches'!$C$2:$C$2000,"<="&DATE(2025,3,31)) -> 1 | J11: =COUNTIFS('Separate Branches'!$C$2:$C$2000,">="&DATE(2024,10,1),'Separate Branches'!$C$2:$C$2000,"<="&DATE(2024,12,31)) -> 1 | K11: =COUNTIFS('Separate Branches'!$C$2:$C$2000,">="&DATE(2024,7,1),'Separate Branches'!$C$2:$C$2000,"<="&DATE(2024,9,30)) -> 1 | L11: =COUNTIFS('Separate Branches'!$C$2:$C$2000,">="&DATE(2024,4,1),'Separate Branches'!$C$2:$C$2000,"<="&DATE(2024,6,30)) -> 0 | M11: =COUNTIFS('Separate Branches'!$C$2:$C$2000,">="&DATE(2024,1,1),'Separate Branches'!$C$2:$C$2000,"<="&DATE(2024,3,31)) -> 1 | N11: =COUNTIFS('Separate Branches'!$C$2:$C$2000,">="&DATE(2023,10,1),'Separate Branches'!$C$2:$C$2000,"<="&DATE(2023,12,31)) -> 0 | O11: =COUNTIFS('Separate Branches'!$C$2:$C$2000,">="&DATE(2023,7,1),'Separate Branches'!$C$2:$C$2000,"<="&DATE(2023,9,30)) -> 1 | P11: =COUNTIFS('Separate Branches'!$C$2:$C$2000,">="&DATE(2023,4,1),'Separate Branches'!$C$2:$C$2000,"<="&DATE(2023,6,30)) -> 0 | Q11: =COUNTIFS('Separate Branches'!$C$2:$C$2000,">="&DATE(2023,1,1),'Separate Branches'!$C$2:$C$2000,"<="&DATE(2023,3,31)) -> 0 | R11: =COUNTIFS('Separate Branches'!$C$2:$C$2000,">="&DATE(2022,10,1),'Separate Branches'!$C$2:$C$2000,"<="&DATE(2022,12,31)) -> 1 | S11: =COUNTIFS('Separate Branches'!$C$2:$C$2000,">="&DATE(2022,7,1),'Separate Branches'!$C$2:$C$2000,"<="&DATE(2022,9,30)) -> 0 | T11: =COUNTIFS('Separate Branches'!$C$2:$C$2000,">="&DATE(2022,4,1),'Separate Branches'!$C$2:$C$2000,"<="&DATE(2022,6,30)) -> 2 | U11: =COUNTIFS('Separate Branches'!$C$2:$C$2000,">="&DATE(2022,1,1),'Separate Branches'!$C$2:$C$2000,"<="&DATE(2022,3,31)) -> 2 | V11: =COUNTIFS('Separate Branches'!$C$2:$C$2000,">="&DATE(2021,10,1),'Separate Branches'!$C$2:$C$2000,"<="&DATE(2021,12,31)) -> 0 | W11: =COUNTIFS('Separate Branches'!$C$2:$C$2000,">="&DATE(2021,7,1),'Separate Branches'!$C$2:$C$2000,"<="&DATE(2021,9,30)) -> 1 | X11: =COUNTIFS('Separate Branches'!$C$2:$C$2000,">="&DATE(2021,4,1),'Separate Branches'!$C$2:$C$2000,"<="&DATE(2021,6,30)) -> 1 | Y11: =COUNTIFS('Separate Branches'!$C$2:$C$2000,">="&DATE(2021,1,1),'Separate Branches'!$C$2:$C$2000,"<="&DATE(2021,3,31)) -> 2 | Z11: =COUNTIFS('Separate Branches'!$C$2:$C$2000,">="&DATE(2020,10,1),'Separate Branches'!$C$2:$C$2000,"<="&DATE(2020,12,31)) -> 0
A12: Thread readability & structure | B12: Nested / quoted content readability | C12: =COUNTIFS('Quoted Readability'!$C$2:$C$2000,">="&DATE(2026,7,1),'Quoted Readability'!$C$2:$C$2000,"<="&DATE(2026,9,30)) -> 2 | D12: =COUNTIFS('Quoted Readability'!$C$2:$C$2000,">="&DATE(2026,4,1),'Quoted Readability'!$C$2:$C$2000,"<="&DATE(2026,6,30)) -> 2 | E12: =COUNTIFS('Quoted Readability'!$C$2:$C$2000,">="&DATE(2026,1,1),'Quoted Readability'!$C$2:$C$2000,"<="&DATE(2026,3,31)) -> 1 | F12: =COUNTIFS('Quoted Readability'!$C$2:$C$2000,">="&DATE(2025,10,1),'Quoted Readability'!$C$2:$C$2000,"<="&DATE(2025,12,31)) -> 0 | G12: =COUNTIFS('Quoted Readability'!$C$2:$C$2000,">="&DATE(2025,7,1),'Quoted Readability'!$C$2:$C$2000,"<="&DATE(2025,9,30)) -> 0 | H12: =COUNTIFS('Quoted Readability'!$C$2:$C$2000,">="&DATE(2025,4,1),'Quoted Readability'!$C$2:$C$2000,"<="&DATE(2025,6,30)) -> 0 | I12: =COUNTIFS('Quoted Readability'!$C$2:$C$2000,">="&DATE(2025,1,1),'Quoted Readability'!$C$2:$C$2000,"<="&DATE(2025,3,31)) -> 1 | J12: =COUNTIFS('Quoted Readability'!$C$2:$C$2000,">="&DATE(2024,10,1),'Quoted Readability'!$C$2:$C$2000,"<="&DATE(2024,12,31)) -> 0 | K12: =COUNTIFS('Quoted Readability'!$C$2:$C$2000,">="&DATE(2024,7,1),'Quoted Readability'!$C$2:$C$2000,"<="&DATE(2024,9,30)) -> 0 | L12: =COUNTIFS('Quoted Readability'!$C$2:$C$2000,">="&DATE(2024,4,1),'Quoted Readability'!$C$2:$C$2000,"<="&DATE(2024,6,30)) -> 0 | M12: =COUNTIFS('Quoted Readability'!$C$2:$C$2000,">="&DATE(2024,1,1),'Quoted Readability'!$C$2:$C$2000,"<="&DATE(2024,3,31)) -> 2 | N12: =COUNTIFS('Quoted Readability'!$C$2:$C$2000,">="&DATE(2023,10,1),'Quoted Readability'!$C$2:$C$2000,"<="&DATE(2023,12,31)) -> 0 | O12: =COUNTIFS('Quoted Readability'!$C$2:$C$2000,">="&DATE(2023,7,1),'Quoted Readability'!$C$2:$C$2000,"<="&DATE(2023,9,30)) -> 0 | P12: =COUNTIFS('Quoted Readability'!$C$2:$C$2000,">="&DATE(2023,4,1),'Quoted Readability'!$C$2:$C$2000,"<="&DATE(2023,6,30)) -> 0 | Q12: =COUNTIFS('Quoted Readability'!$C$2:$C$2000,">="&DATE(2023,1,1),'Quoted Readability'!$C$2:$C$2000,"<="&DATE(2023,3,31)) -> 0 | R12: =COUNTIFS('Quoted Readability'!$C$2:$C$2000,">="&DATE(2022,10,1),'Quoted Readability'!$C$2:$C$2000,"<="&DATE(2022,12,31)) -> 0 | S12: =COUNTIFS('Quoted Readability'!$C$2:$C$2000,">="&DATE(2022,7,1),'Quoted Readability'!$C$2:$C$2000,"<="&DATE(2022,9,30)) -> 0 | T12: =COUNTIFS('Quoted Readability'!$C$2:$C$2000,">="&DATE(2022,4,1),'Quoted Readability'!$C$2:$C$2000,"<="&DATE(2022,6,30)) -> 1 | U12: =COUNTIFS('Quoted Readability'!$C$2:$C$2000,">="&DATE(2022,1,1),'Quoted Readability'!$C$2:$C$2000,"<="&DATE(2022,3,31)) -> 0 | V12: =COUNTIFS('Quoted Readability'!$C$2:$C$2000,">="&DATE(2021,10,1),'Quoted Readability'!$C$2:$C$2000,"<="&DATE(2021,12,31)) -> 0 | W12: =COUNTIFS('Quoted Readability'!$C$2:$C$2000,">="&DATE(2021,7,1),'Quoted Readability'!$C$2:$C$2000,"<="&DATE(2021,9,30)) -> 0 | X12: =COUNTIFS('Quoted Readability'!$C$2:$C$2000,">="&DATE(2021,4,1),'Quoted Readability'!$C$2:$C$2000,"<="&DATE(2021,6,30)) -> 0 | Y12: =COUNTIFS('Quoted Readability'!$C$2:$C$2000,">="&DATE(2021,1,1),'Quoted Readability'!$C$2:$C$2000,"<="&DATE(2021,3,31)) -> 0 | Z12: =COUNTIFS('Quoted Readability'!$C$2:$C$2000,">="&DATE(2020,10,1),'Quoted Readability'!$C$2:$C$2000,"<="&DATE(2020,12,31)) -> 0
A13: Attachments in threads | B13: Attachment discovery & access | C13: =COUNTIFS('Attachment Discovery'!$C$2:$C$2000,">="&DATE(2026,7,1),'Attachment Discovery'!$C$2:$C$2000,"<="&DATE(2026,9,30)) -> 0 | D13: =COUNTIFS('Attachment Discovery'!$C$2:$C$2000,">="&DATE(2026,4,1),'Attachment Discovery'!$C$2:$C$2000,"<="&DATE(2026,6,30)) -> 4 | E13: =COUNTIFS('Attachment Discovery'!$C$2:$C$2000,">="&DATE(2026,1,1),'Attachment Discovery'!$C$2:$C$2000,"<="&DATE(2026,3,31)) -> 1 | F13: =COUNTIFS('Attachment Discovery'!$C$2:$C$2000,">="&DATE(2025,10,1),'Attachment Discovery'!$C$2:$C$2000,"<="&DATE(2025,12,31)) -> 1 | G13: =COUNTIFS('Attachment Discovery'!$C$2:$C$2000,">="&DATE(2025,7,1),'Attachment Discovery'!$C$2:$C$2000,"<="&DATE(2025,9,30)) -> 2 | H13: =COUNTIFS('Attachment Discovery'!$C$2:$C$2000,">="&DATE(2025,4,1),'Attachment Discovery'!$C$2:$C$2000,"<="&DATE(2025,6,30)) -> 1 | I13: =COUNTIFS('Attachment Discovery'!$C$2:$C$2000,">="&DATE(2025,1,1),'Attachment Discovery'!$C$2:$C$2000,"<="&DATE(2025,3,31)) -> 1 | J13: =COUNTIFS('Attachment Discovery'!$C$2:$C$2000,">="&DATE(2024,10,1),'Attachment Discovery'!$C$2:$C$2000,"<="&DATE(2024,12,31)) -> 1 | K13: =COUNTIFS('Attachment Discovery'!$C$2:$C$2000,">="&DATE(2024,7,1),'Attachment Discovery'!$C$2:$C$2000,"<="&DATE(2024,9,30)) -> 0 | L13: =COUNTIFS('Attachment Discovery'!$C$2:$C$2000,">="&DATE(2024,4,1),'Attachment Discovery'!$C$2:$C$2000,"<="&DATE(2024,6,30)) -> 2 | M13: =COUNTIFS('Attachment Discovery'!$C$2:$C$2000,">="&DATE(2024,1,1),'Attachment Discovery'!$C$2:$C$2000,"<="&DATE(2024,3,31)) -> 2 | N13: =COUNTIFS('Attachment Discovery'!$C$2:$C$2000,">="&DATE(2023,10,1),'Attachment Discovery'!$C$2:$C$2000,"<="&DATE(2023,12,31)) -> 1 | O13: =COUNTIFS('Attachment Discovery'!$C$2:$C$2000,">="&DATE(2023,7,1),'Attachment Discovery'!$C$2:$C$2000,"<="&DATE(2023,9,30)) -> 2 | P13: =COUNTIFS('Attachment Discovery'!$C$2:$C$2000,">="&DATE(2023,4,1),'Attachment Discovery'!$C$2:$C$2000,"<="&DATE(2023,6,30)) -> 0 | Q13: =COUNTIFS('Attachment Discovery'!$C$2:$C$2000,">="&DATE(2023,1,1),'Attachment Discovery'!$C$2:$C$2000,"<="&DATE(2023,3,31)) -> 3 | R13: =COUNTIFS('Attachment Discovery'!$C$2:$C$2000,">="&DATE(2022,10,1),'Attachment Discovery'!$C$2:$C$2000,"<="&DATE(2022,12,31)) -> 1 | S13: =COUNTIFS('Attachment Discovery'!$C$2:$C$2000,">="&DATE(2022,7,1),'Attachment Discovery'!$C$2:$C$2000,"<="&DATE(2022,9,30)) -> 3 | T13: =COUNTIFS('Attachment Discovery'!$C$2:$C$2000,">="&DATE(2022,4,1),'Attachment Discovery'!$C$2:$C$2000,"<="&DATE(2022,6,30)) -> 2 | U13: =COUNTIFS('Attachment Discovery'!$C$2:$C$2000,">="&DATE(2022,1,1),'Attachment Discovery'!$C$2:$C$2000,"<="&DATE(2022,3,31)) -> 1 | V13: =COUNTIFS('Attachment Discovery'!$C$2:$C$2000,">="&DATE(2021,10,1),'Attachment Discovery'!$C$2:$C$2000,"<="&DATE(2021,12,31)) -> 0 | W13: =COUNTIFS('Attachment Discovery'!$C$2:$C$2000,">="&DATE(2021,7,1),'Attachment Discovery'!$C$2:$C$2000,"<="&DATE(2021,9,30)) -> 0 | X13: =COUNTIFS('Attachment Discovery'!$C$2:$C$2000,">="&DATE(2021,4,1),'Attachment Discovery'!$C$2:$C$2000,"<="&DATE(2021,6,30)) -> 0 | Y13: =COUNTIFS('Attachment Discovery'!$C$2:$C$2000,">="&DATE(2021,1,1),'Attachment Discovery'!$C$2:$C$2000,"<="&DATE(2021,3,31)) -> 1 | Z13: =COUNTIFS('Attachment Discovery'!$C$2:$C$2000,">="&DATE(2020,10,1),'Attachment Discovery'!$C$2:$C$2000,"<="&DATE(2020,12,31)) -> 0
A14: Attachments in threads | B14: Attachment carry-over | C14: =COUNTIFS('Attachment Carry-over'!$C$2:$C$2000,">="&DATE(2026,7,1),'Attachment Carry-over'!$C$2:$C$2000,"<="&DATE(2026,9,30)) -> 0 | D14: =COUNTIFS('Attachment Carry-over'!$C$2:$C$2000,">="&DATE(2026,4,1),'Attachment Carry-over'!$C$2:$C$2000,"<="&DATE(2026,6,30)) -> 0 | E14: =COUNTIFS('Attachment Carry-over'!$C$2:$C$2000,">="&DATE(2026,1,1),'Attachment Carry-over'!$C$2:$C$2000,"<="&DATE(2026,3,31)) -> 0 | F14: =COUNTIFS('Attachment Carry-over'!$C$2:$C$2000,">="&DATE(2025,10,1),'Attachment Carry-over'!$C$2:$C$2000,"<="&DATE(2025,12,31)) -> 0 | G14: =COUNTIFS('Attachment Carry-over'!$C$2:$C$2000,">="&DATE(2025,7,1),'Attachment Carry-over'!$C$2:$C$2000,"<="&DATE(2025,9,30)) -> 0 | H14: =COUNTIFS('Attachment Carry-over'!$C$2:$C$2000,">="&DATE(2025,4,1),'Attachment Carry-over'!$C$2:$C$2000,"<="&DATE(2025,6,30)) -> 0 | I14: =COUNTIFS('Attachment Carry-over'!$C$2:$C$2000,">="&DATE(2025,1,1),'Attachment Carry-over'!$C$2:$C$2000,"<="&DATE(2025,3,31)) -> 1 | J14: =COUNTIFS('Attachment Carry-over'!$C$2:$C$2000,">="&DATE(2024,10,1),'Attachment Carry-over'!$C$2:$C$2000,"<="&DATE(2024,12,31)) -> 0 | K14: =COUNTIFS('Attachment Carry-over'!$C$2:$C$2000,">="&DATE(2024,7,1),'Attachment Carry-over'!$C$2:$C$2000,"<="&DATE(2024,9,30)) -> 0 | L14: =COUNTIFS('Attachment Carry-over'!$C$2:$C$2000,">="&DATE(2024,4,1),'Attachment Carry-over'!$C$2:$C$2000,"<="&DATE(2024,6,30)) -> 0 | M14: =COUNTIFS('Attachment Carry-over'!$C$2:$C$2000,">="&DATE(2024,1,1),'Attachment Carry-over'!$C$2:$C$2000,"<="&DATE(2024,3,31)) -> 0 | N14: =COUNTIFS('Attachment Carry-over'!$C$2:$C$2000,">="&DATE(2023,10,1),'Attachment Carry-over'!$C$2:$C$2000,"<="&DATE(2023,12,31)) -> 0 | O14: =COUNTIFS('Attachment Carry-over'!$C$2:$C$2000,">="&DATE(2023,7,1),'Attachment Carry-over'!$C$2:$C$2000,"<="&DATE(2023,9,30)) -> 0 | P14: =COUNTIFS('Attachment Carry-over'!$C$2:$C$2000,">="&DATE(2023,4,1),'Attachment Carry-over'!$C$2:$C$2000,"<="&DATE(2023,6,30)) -> 0 | Q14: =COUNTIFS('Attachment Carry-over'!$C$2:$C$2000,">="&DATE(2023,1,1),'Attachment Carry-over'!$C$2:$C$2000,"<="&DATE(2023,3,31)) -> 0 | R14: =COUNTIFS('Attachment Carry-over'!$C$2:$C$2000,">="&DATE(2022,10,1),'Attachment Carry-over'!$C$2:$C$2000,"<="&DATE(2022,12,31)) -> 0 | S14: =COUNTIFS('Attachment Carry-over'!$C$2:$C$2000,">="&DATE(2022,7,1),'Attachment Carry-over'!$C$2:$C$2000,"<="&DATE(2022,9,30)) -> 0 | T14: =COUNTIFS('Attachment Carry-over'!$C$2:$C$2000,">="&DATE(2022,4,1),'Attachment Carry-over'!$C$2:$C$2000,"<="&DATE(2022,6,30)) -> 0 | U14: =COUNTIFS('Attachment Carry-over'!$C$2:$C$2000,">="&DATE(2022,1,1),'Attachment Carry-over'!$C$2:$C$2000,"<="&DATE(2022,3,31)) -> 0 | V14: =COUNTIFS('Attachment Carry-over'!$C$2:$C$2000,">="&DATE(2021,10,1),'Attachment Carry-over'!$C$2:$C$2000,"<="&DATE(2021,12,31)) -> 0 | W14: =COUNTIFS('Attachment Carry-over'!$C$2:$C$2000,">="&DATE(2021,7,1),'Attachment Carry-over'!$C$2:$C$2000,"<="&DATE(2021,9,30)) -> 0 | X14: =COUNTIFS('Attachment Carry-over'!$C$2:$C$2000,">="&DATE(2021,4,1),'Attachment Carry-over'!$C$2:$C$2000,"<="&DATE(2021,6,30)) -> 0 | Y14: =COUNTIFS('Attachment Carry-over'!$C$2:$C$2000,">="&DATE(2021,1,1),'Attachment Carry-over'!$C$2:$C$2000,"<="&DATE(2021,3,31)) -> 0 | Z14: =COUNTIFS('Attachment Carry-over'!$C$2:$C$2000,">="&DATE(2020,10,1),'Attachment Carry-over'!$C$2:$C$2000,"<="&DATE(2020,12,31)) -> 0
A15: Thread reliability | B15: Message rendering | C15: =COUNTIFS('Message Rendering'!$C$2:$C$2000,">="&DATE(2026,7,1),'Message Rendering'!$C$2:$C$2000,"<="&DATE(2026,9,30)) -> 1 | D15: =COUNTIFS('Message Rendering'!$C$2:$C$2000,">="&DATE(2026,4,1),'Message Rendering'!$C$2:$C$2000,"<="&DATE(2026,6,30)) -> 3 | E15: =COUNTIFS('Message Rendering'!$C$2:$C$2000,">="&DATE(2026,1,1),'Message Rendering'!$C$2:$C$2000,"<="&DATE(2026,3,31)) -> 2 | F15: =COUNTIFS('Message Rendering'!$C$2:$C$2000,">="&DATE(2025,10,1),'Message Rendering'!$C$2:$C$2000,"<="&DATE(2025,12,31)) -> 1 | G15: =COUNTIFS('Message Rendering'!$C$2:$C$2000,">="&DATE(2025,7,1),'Message Rendering'!$C$2:$C$2000,"<="&DATE(2025,9,30)) -> 1 | H15: =COUNTIFS('Message Rendering'!$C$2:$C$2000,">="&DATE(2025,4,1),'Message Rendering'!$C$2:$C$2000,"<="&DATE(2025,6,30)) -> 1 | I15: =COUNTIFS('Message Rendering'!$C$2:$C$2000,">="&DATE(2025,1,1),'Message Rendering'!$C$2:$C$2000,"<="&DATE(2025,3,31)) -> 3 | J15: =COUNTIFS('Message Rendering'!$C$2:$C$2000,">="&DATE(2024,10,1),'Message Rendering'!$C$2:$C$2000,"<="&DATE(2024,12,31)) -> 0 | K15: =COUNTIFS('Message Rendering'!$C$2:$C$2000,">="&DATE(2024,7,1),'Message Rendering'!$C$2:$C$2000,"<="&DATE(2024,9,30)) -> 1 | L15: =COUNTIFS('Message Rendering'!$C$2:$C$2000,">="&DATE(2024,4,1),'Message Rendering'!$C$2:$C$2000,"<="&DATE(2024,6,30)) -> 2 | M15: =COUNTIFS('Message Rendering'!$C$2:$C$2000,">="&DATE(2024,1,1),'Message Rendering'!$C$2:$C$2000,"<="&DATE(2024,3,31)) -> 2 | N15: =COUNTIFS('Message Rendering'!$C$2:$C$2000,">="&DATE(2023,10,1),'Message Rendering'!$C$2:$C$2000,"<="&DATE(2023,12,31)) -> 1 | O15: =COUNTIFS('Message Rendering'!$C$2:$C$2000,">="&DATE(2023,7,1),'Message Rendering'!$C$2:$C$2000,"<="&DATE(2023,9,30)) -> 1 | P15: =COUNTIFS('Message Rendering'!$C$2:$C$2000,">="&DATE(2023,4,1),'Message Rendering'!$C$2:$C$2000,"<="&DATE(2023,6,30)) -> 4 | Q15: =COUNTIFS('Message Rendering'!$C$2:$C$2000,">="&DATE(2023,1,1),'Message Rendering'!$C$2:$C$2000,"<="&DATE(2023,3,31)) -> 2 | R15: =COUNTIFS('Message Rendering'!$C$2:$C$2000,">="&DATE(2022,10,1),'Message Rendering'!$C$2:$C$2000,"<="&DATE(2022,12,31)) -> 0 | S15: =COUNTIFS('Message Rendering'!$C$2:$C$2000,">="&DATE(2022,7,1),'Message Rendering'!$C$2:$C$2000,"<="&DATE(2022,9,30)) -> 1 | T15: =COUNTIFS('Message Rendering'!$C$2:$C$2000,">="&DATE(2022,4,1),'Message Rendering'!$C$2:$C$2000,"<="&DATE(2022,6,30)) -> 1 | U15: =COUNTIFS('Message Rendering'!$C$2:$C$2000,">="&DATE(2022,1,1),'Message Rendering'!$C$2:$C$2000,"<="&DATE(2022,3,31)) -> 2 | V15: =COUNTIFS('Message Rendering'!$C$2:$C$2000,">="&DATE(2021,10,1),'Message Rendering'!$C$2:$C$2000,"<="&DATE(2021,12,31)) -> 0 | W15: =COUNTIFS('Message Rendering'!$C$2:$C$2000,">="&DATE(2021,7,1),'Message Rendering'!$C$2:$C$2000,"<="&DATE(2021,9,30)) -> 0 | X15: =COUNTIFS('Message Rendering'!$C$2:$C$2000,">="&DATE(2021,4,1),'Message Rendering'!$C$2:$C$2000,"<="&DATE(2021,6,30)) -> 0 | Y15: =COUNTIFS('Message Rendering'!$C$2:$C$2000,">="&DATE(2021,1,1),'Message Rendering'!$C$2:$C$2000,"<="&DATE(2021,3,31)) -> 0 | Z15: =COUNTIFS('Message Rendering'!$C$2:$C$2000,">="&DATE(2020,10,1),'Message Rendering'!$C$2:$C$2000,"<="&DATE(2020,12,31)) -> 0
A16: Thread sharing | B16: Attach conversation to a new email | C16: =COUNTIFS('Attach Conversation'!$C$2:$C$2000,">="&DATE(2026,7,1),'Attach Conversation'!$C$2:$C$2000,"<="&DATE(2026,9,30)) -> 1 | D16: =COUNTIFS('Attach Conversation'!$C$2:$C$2000,">="&DATE(2026,4,1),'Attach Conversation'!$C$2:$C$2000,"<="&DATE(2026,6,30)) -> 1 | E16: =COUNTIFS('Attach Conversation'!$C$2:$C$2000,">="&DATE(2026,1,1),'Attach Conversation'!$C$2:$C$2000,"<="&DATE(2026,3,31)) -> 0 | F16: =COUNTIFS('Attach Conversation'!$C$2:$C$2000,">="&DATE(2025,10,1),'Attach Conversation'!$C$2:$C$2000,"<="&DATE(2025,12,31)) -> 0 | G16: =COUNTIFS('Attach Conversation'!$C$2:$C$2000,">="&DATE(2025,7,1),'Attach Conversation'!$C$2:$C$2000,"<="&DATE(2025,9,30)) -> 0 | H16: =COUNTIFS('Attach Conversation'!$C$2:$C$2000,">="&DATE(2025,4,1),'Attach Conversation'!$C$2:$C$2000,"<="&DATE(2025,6,30)) -> 0 | I16: =COUNTIFS('Attach Conversation'!$C$2:$C$2000,">="&DATE(2025,1,1),'Attach Conversation'!$C$2:$C$2000,"<="&DATE(2025,3,31)) -> 0 | J16: =COUNTIFS('Attach Conversation'!$C$2:$C$2000,">="&DATE(2024,10,1),'Attach Conversation'!$C$2:$C$2000,"<="&DATE(2024,12,31)) -> 0 | K16: =COUNTIFS('Attach Conversation'!$C$2:$C$2000,">="&DATE(2024,7,1),'Attach Conversation'!$C$2:$C$2000,"<="&DATE(2024,9,30)) -> 0 | L16: =COUNTIFS('Attach Conversation'!$C$2:$C$2000,">="&DATE(2024,4,1),'Attach Conversation'!$C$2:$C$2000,"<="&DATE(2024,6,30)) -> 0 | M16: =COUNTIFS('Attach Conversation'!$C$2:$C$2000,">="&DATE(2024,1,1),'Attach Conversation'!$C$2:$C$2000,"<="&DATE(2024,3,31)) -> 0 | N16: =COUNTIFS('Attach Conversation'!$C$2:$C$2000,">="&DATE(2023,10,1),'Attach Conversation'!$C$2:$C$2000,"<="&DATE(2023,12,31)) -> 0 | O16: =COUNTIFS('Attach Conversation'!$C$2:$C$2000,">="&DATE(2023,7,1),'Attach Conversation'!$C$2:$C$2000,"<="&DATE(2023,9,30)) -> 0 | P16: =COUNTIFS('Attach Conversation'!$C$2:$C$2000,">="&DATE(2023,4,1),'Attach Conversation'!$C$2:$C$2000,"<="&DATE(2023,6,30)) -> 0 | Q16: =COUNTIFS('Attach Conversation'!$C$2:$C$2000,">="&DATE(2023,1,1),'Attach Conversation'!$C$2:$C$2000,"<="&DATE(2023,3,31)) -> 0 | R16: =COUNTIFS('Attach Conversation'!$C$2:$C$2000,">="&DATE(2022,10,1),'Attach Conversation'!$C$2:$C$2000,"<="&DATE(2022,12,31)) -> 0 | S16: =COUNTIFS('Attach Conversation'!$C$2:$C$2000,">="&DATE(2022,7,1),'Attach Conversation'!$C$2:$C$2000,"<="&DATE(2022,9,30)) -> 0 | T16: =COUNTIFS('Attach Conversation'!$C$2:$C$2000,">="&DATE(2022,4,1),'Attach Conversation'!$C$2:$C$2000,"<="&DATE(2022,6,30)) -> 0 | U16: =COUNTIFS('Attach Conversation'!$C$2:$C$2000,">="&DATE(2022,1,1),'Attach Conversation'!$C$2:$C$2000,"<="&DATE(2022,3,31)) -> 0 | V16: =COUNTIFS('Attach Conversation'!$C$2:$C$2000,">="&DATE(2021,10,1),'Attach Conversation'!$C$2:$C$2000,"<="&DATE(2021,12,31)) -> 0 | W16: =COUNTIFS('Attach Conversation'!$C$2:$C$2000,">="&DATE(2021,7,1),'Attach Conversation'!$C$2:$C$2000,"<="&DATE(2021,9,30)) -> 0 | X16: =COUNTIFS('Attach Conversation'!$C$2:$C$2000,">="&DATE(2021,4,1),'Attach Conversation'!$C$2:$C$2000,"<="&DATE(2021,6,30)) -> 0 | Y16: =COUNTIFS('Attach Conversation'!$C$2:$C$2000,">="&DATE(2021,1,1),'Attach Conversation'!$C$2:$C$2000,"<="&DATE(2021,3,31)) -> 0 | Z16: =COUNTIFS('Attach Conversation'!$C$2:$C$2000,">="&DATE(2020,10,1),'Attach Conversation'!$C$2:$C$2000,"<="&DATE(2020,12,31)) -> 0
A17: Thread sharing | B17: Print full conversation | C17: =COUNTIFS('Print Conversation'!$C$2:$C$2000,">="&DATE(2026,7,1),'Print Conversation'!$C$2:$C$2000,"<="&DATE(2026,9,30)) -> 0 | D17: =COUNTIFS('Print Conversation'!$C$2:$C$2000,">="&DATE(2026,4,1),'Print Conversation'!$C$2:$C$2000,"<="&DATE(2026,6,30)) -> 0 | E17: =COUNTIFS('Print Conversation'!$C$2:$C$2000,">="&DATE(2026,1,1),'Print Conversation'!$C$2:$C$2000,"<="&DATE(2026,3,31)) -> 0 | F17: =COUNTIFS('Print Conversation'!$C$2:$C$2000,">="&DATE(2025,10,1),'Print Conversation'!$C$2:$C$2000,"<="&DATE(2025,12,31)) -> 1 | G17: =COUNTIFS('Print Conversation'!$C$2:$C$2000,">="&DATE(2025,7,1),'Print Conversation'!$C$2:$C$2000,"<="&DATE(2025,9,30)) -> 0 | H17: =COUNTIFS('Print Conversation'!$C$2:$C$2000,">="&DATE(2025,4,1),'Print Conversation'!$C$2:$C$2000,"<="&DATE(2025,6,30)) -> 0 | I17: =COUNTIFS('Print Conversation'!$C$2:$C$2000,">="&DATE(2025,1,1),'Print Conversation'!$C$2:$C$2000,"<="&DATE(2025,3,31)) -> 0 | J17: =COUNTIFS('Print Conversation'!$C$2:$C$2000,">="&DATE(2024,10,1),'Print Conversation'!$C$2:$C$2000,"<="&DATE(2024,12,31)) -> 1 | K17: =COUNTIFS('Print Conversation'!$C$2:$C$2000,">="&DATE(2024,7,1),'Print Conversation'!$C$2:$C$2000,"<="&DATE(2024,9,30)) -> 0 | L17: =COUNTIFS('Print Conversation'!$C$2:$C$2000,">="&DATE(2024,4,1),'Print Conversation'!$C$2:$C$2000,"<="&DATE(2024,6,30)) -> 0 | M17: =COUNTIFS('Print Conversation'!$C$2:$C$2000,">="&DATE(2024,1,1),'Print Conversation'!$C$2:$C$2000,"<="&DATE(2024,3,31)) -> 1 | N17: =COUNTIFS('Print Conversation'!$C$2:$C$2000,">="&DATE(2023,10,1),'Print Conversation'!$C$2:$C$2000,"<="&DATE(2023,12,31)) -> 0 | O17: =COUNTIFS('Print Conversation'!$C$2:$C$2000,">="&DATE(2023,7,1),'Print Conversation'!$C$2:$C$2000,"<="&DATE(2023,9,30)) -> 0 | P17: =COUNTIFS('Print Conversation'!$C$2:$C$2000,">="&DATE(2023,4,1),'Print Conversation'!$C$2:$C$2000,"<="&DATE(2023,6,30)) -> 0 | Q17: =COUNTIFS('Print Conversation'!$C$2:$C$2000,">="&DATE(2023,1,1),'Print Conversation'!$C$2:$C$2000,"<="&DATE(2023,3,31)) -> 0 | R17: =COUNTIFS('Print Conversation'!$C$2:$C$2000,">="&DATE(2022,10,1),'Print Conversation'!$C$2:$C$2000,"<="&DATE(2022,12,31)) -> 1 | S17: =COUNTIFS('Print Conversation'!$C$2:$C$2000,">="&DATE(2022,7,1),'Print Conversation'!$C$2:$C$2000,"<="&DATE(2022,9,30)) -> 0 | T17: =COUNTIFS('Print Conversation'!$C$2:$C$2000,">="&DATE(2022,4,1),'Print Conversation'!$C$2:$C$2000,"<="&DATE(2022,6,30)) -> 1 | U17: =COUNTIFS('Print Conversation'!$C$2:$C$2000,">="&DATE(2022,1,1),'Print Conversation'!$C$2:$C$2000,"<="&DATE(2022,3,31)) -> 0 | V17: =COUNTIFS('Print Conversation'!$C$2:$C$2000,">="&DATE(2021,10,1),'Print Conversation'!$C$2:$C$2000,"<="&DATE(2021,12,31)) -> 0 | W17: =COUNTIFS('Print Conversation'!$C$2:$C$2000,">="&DATE(2021,7,1),'Print Conversation'!$C$2:$C$2000,"<="&DATE(2021,9,30)) -> 2 | X17: =COUNTIFS('Print Conversation'!$C$2:$C$2000,">="&DATE(2021,4,1),'Print Conversation'!$C$2:$C$2000,"<="&DATE(2021,6,30)) -> 1 | Y17: =COUNTIFS('Print Conversation'!$C$2:$C$2000,">="&DATE(2021,1,1),'Print Conversation'!$C$2:$C$2000,"<="&DATE(2021,3,31)) -> 1 | Z17: =COUNTIFS('Print Conversation'!$C$2:$C$2000,">="&DATE(2020,10,1),'Print Conversation'!$C$2:$C$2000,"<="&DATE(2020,12,31)) -> 0
B18: Total | C18: =SUM(C5:C17) -> 13 | D18: =SUM(D5:D17) -> 36 | E18: =SUM(E5:E17) -> 19 | F18: =SUM(F5:F17) -> 17 | G18: =SUM(G5:G17) -> 16 | H18: =SUM(H5:H17) -> 18 | I18: =SUM(I5:I17) -> 20 | J18: =SUM(J5:J17) -> 13 | ... Z18: =SUM(Z5:Z17) -> 4

Sheet Unclassified Feedback
A1: Account ID | B1: Feedback Date | C1: NPS Score | D1: Plan | E1: Partner | F1: Source | G1: Feedback | H1: Reason Not Classified
A2: 10000114 | B2: 46252 | C2: 2 | D2: Pro | E2: Bluehost | F2: NPS | G2: The mobile app is brutal. Trying to review all of the emails in a thread takes forever. I frequently have to go back to the desktop browser to get the emails to load. [Improvement: Fix that] | H2: Issue lies outside Conversation View (search, delivery, deletion, compose, performance, etc.).
A3: 10836957 | B3: 46250 | C3: 8 | D3: Pro | E3: Secureserver | F3: NPS | G3: some times it is confusing to follow conversations in the same thread [Improvement: find a way to separate reply and follow up mails] | H3: Complaint or request too vague to identify which underlying thread problem is meant.
A4: 9983249 | B4: 46244 | C4: 10 | D4: Pro | E4: Secureserver | F4: NPS | G4: The layout and feel is better than Outlook, Yes 1 change i would request is Mail trail needs to be seperated. | H4: Complaint or request too vague to identify which underlying thread problem is meant.
A5: 8999462 | B5: 46238 | C5: 9 | D5: Pro | E5: Vodien | F5: NPS | G5: Easy to use. However, it can be even better if it has an AI feature to collate an email thread to summarize the contents of the thread discussion. | H5: Describes a real thread-related need, but it does not map to any predefined sub-theme.
A6: 10822667 | B6: 46237 | C6: 1 | D6: Ultra | E6: Secureserver | F6: NPS | G6: The way that email threads is organised is terrible. [Improvement: email thread organisation.] | H6: Generic complaint about thread usability; no specific underlying problem identifiable.
A7: 10997771 | B7: 46231 | C7: 7 | D7: Free | E7: Hostinger | F7: NPS | G7: The way the emails get stacked and displayed is confusing and doesn't follow the same process as gmail or other mainstream mail providers which causes time delays and is inefficient. [Improvement: Make the email chains easier to follow. Either follow the process Gmail and others use or be inventive and make it even better.] | H7: Generic complaint about thread usability; no specific underlying problem identifiable.
A8: 3105126 | B8: 46227 | C8: 4 | D8: Premium | E8: name.com | F8: NPS | G8: Threads are extremely unwieldy. | H8: Generic complaint about thread usability; no specific underlying problem identifiable.
A9: 7134577 | B9: 46226 | C9: 6 | D9: Pro | E9: WordPress.com | F9: NPS | G9: The email layout is not clean enough. Too costly for what you offer. Nothing special. I do not like the way the reply emails stack up. Confusing and not easily overseeable. [Improvement: See my comments. Make it cleaner.] | H9: Generic complaint about thread usability; no specific underlying problem identifiable.
A10: 5348995 | B10: 46222 | C10: 6 | D10: Free | E10: Hostinger | F10: NPS | G10: Blocking emails should not be a paid feature. With the high amount of spam, that seems like something everyone should have automatically. [Improvement: Make blocking free... Make it easier to find threads and copy email addresses] | H10: Issue lies outside Conversation View (search, delivery, deletion, compose, performance, etc.).
A11: 7881668 | B11: 46216 | C11: 10 | D11: Starter | E11: ResellerClub Newfold | F11: NPS | G11: I have had no difficulty; the email history is visible right away, so there is no need to go to Sent to check. | H11: Positive or neutral feedback; no problem described.
A12: 10239683 | B12: 46211 | C12: 1 | D12: Pro | E12: Secureserver | F12: NPS | G12: All confusing previous GoDaddy version was easy to understand and use. [Improvement: All mails in thread collapsing, causing confusion. Make things easier instead of charging for AI] | H12: Complaint or request too vague to identify which underlying thread problem is meant.
A13: 8645714 | B13: 46203 | C13: 3 | D13: Free | E13: Hostinger | F13: NPS | G13: Keeps asking me to upgrade for this and upgrade for that. Cant search properly, as all e-mails are nested into one, etc | H13: Issue lies outside Conversation View (search, delivery, deletion, compose, performance, etc.).
... A298: 132202 | B298: 44118 | C298: 2 | D298: Free | E298: TSO Host | F298: NPS | G298: nothing is easy. you cant right click to copy. its really hard to keep track of the threads. cant see my old sent emails. i really liked my old Mr Site email it was simple and very good | H298: Generic complaint about thread usability; no specific underlying problem identifiable.

Sheet Message Ordering
A1: Classification Clarity | B1: Account ID | C1: Feedback Date | D1: NPS Score | E1: Plan | F1: Partner | G1: Source | H1: Highlighted Relevant Comment | I1: Full Feedback
A2: Very clear | B2: 3980890 | C2: 46246 | D2: 9 | E2: Pro | F2: WordPress.com | G2: NPS | H2: sometimes the email thread chain is backwards when reading emails in order | I2: sometimes the email thread chain is backwards when reading emails in order [Improvement: order this please x]
A3: Very clear | B3: 5197887 | C3: 46245 | D3: 1 | E3: Pro | F3: Hostinger | G3: NPS | H3: there is no flow in the message. top to bottom. new message comes in the middle instead | I3: there is no flow in the message. top to bottom. new message comes in the middle instead
A4: Very clear | B4: 10819108 | C4: 46217 | D4: 3 | E4: Pro | F4: Secureserver | G4: NPS | H4: Mixed up of old and new mails | I4: Email thread too complicated! Mixed up of old and new mails! Need effort to search the latest mail!
A5: Very clear | B5: 8273859 | C5: 46191 | D5: 5 | E5: Free | F5: HostGator | G5: NPS | H5: the latest reply appearing in the middle of that history | I5: The organisation of the email is poor. It is bad that the email history always shows up, with the latest reply appearing in the middle of that history. It is very confusing. And an email that should only appear in Sent also appears in the inbox. [Improvement: Give the option not to show the email history. And sent is sent... it should not appear anywhere else.]
A6: Very clear | B6: 6848029 | C6: 46183 | D6: 3 | E6: Free | F6: Hostinger | G6: NPS | H6: thread of messages do not follow on in received order | I6: Stacking of emails not logical , they become disorganised and thread of messages do not follow on in received order . A real pain.
A7: Very clear | B7: 9166325 | C7: 46146 | D7: 1 | E7: Pro | F7: Secureserver | G7: NPS | H7: the latest response pops up in the middle | I7: piece of crap, lags, and doesnt attach things properly. the order of messages is confusing in a 50 reply message thread its confusing, the latest response pops up in the middle, you gotta scroll up and down to find past replies but its ten not in order. put things in a linear order, newest reponse coming up as you click, and you can scroll back in chronological order with all attachments under each response. at the moment this is a piece of crap [Improvement: i just told you]
A8: Very clear | B8: 6703977 | C8: 46121 | D8: 6 | E8: Pro | F8: Hostgator Chile | G8: NPS | H8: sometimes the last one sent ends up in the middle of the emails or at the end and does not follow a logical, ordered sequence | I8: It is very cumbersome and unfriendly with the views. It does NOT allow panels to be hidden, and it is unclear when it joins together emails from the same series that are sent... Everything gets tangled. [Improvement: The way it joins emails from a series is bad; sometimes the last one sent ends up in the middle of the emails or at the end and does not follow a logical, ordered sequence. The image formatting also gets lost.]
A9: Very clear | B9: 1487682 | C9: 46079 | D9: 2 | E9: Premium | F9: TSO Host | G9: NPS | H9: Conversation threads are difficult to follow as they appear out of order | I9: Conversation threads are difficult to follow as they appear out of order.
A10: Very clear | B10: 8176083 | C10: 46063 | D10: 8 | E10: Pro | F10: WordPress.com | G10: NPS | H10: the sequence or order gets lost | I10: It is excellent, but I find that in email threads under the same subject the sequence or order gets lost, and it is hard to find the last one.
